Workbook

Sheet PARÂMETROS
A7: PARÂMETROS
A8: Taxa de corretagem (%) | B8: 0.005
A9: Salário mensal alvo | B9: 7500
A10: Meta renda mensal (10%) | B10: =B9*0.1 -> 750
A11: Crescimento dos aportes (mensal) | B11: =POWER(1+0.08,1/12)-1 -> 0.0064340301
A12: Meses simulados | B12: =240 -> 240

Sheet CADASTROS
A6: ATUALIZAÇÃO | B6: NOME | C6: CATEGORIA | D6: PREÇO ATUAL
A7: 45658 | B7: CORP11 | C7: FUNDO IMOBILIÁRIO | D7: R$ 99,99
A8: 45658 | B8: OFFI11 | C8: FUNDO IMOBILIÁRIO | D8: R$ 156,78
A9: 45689 | B9: CENT11 | C9: FUNDO IMOBILIÁRIO | D9: R$ 264,31
A10: 45717 | B10: LOGS11 | C10: FUNDO IMOBILIÁRIO | D10: R$ 820,53
A11: 45748 | B11: GALP11 | C11: FUNDO IMOBILIÁRIO | D11: R$ 757,90
A12: 45778 | B12: ROTA11 | C12: FUNDO IMOBILIÁRIO | D12: R$ 707,37
A13: 45809 | B13: SHOP11 | C13: FUNDO IMOBILIÁRIO | D13: R$ 774,32
A14: 45839 | B14: MALL11 | C14: FUNDO IMOBILIÁRIO | D14: R$ 68,95
A15: 45870 | B15: VEND11 | C15: FUNDO IMOBILIÁRIO | D15: R$ 330,78
A16: 45901 | B16: CRED11 | C16: FUNDO IMOBILIÁRIO | D16: R$ 354,37

Sheet CARTEIRA
A2: Ativo | B2: Tipo | C2: Peso Alvo | D2: % Anual
A3: FII Brasil 1 | B3: FII | C3: 0.5 | D3: 0.08
A4: FII Brasil 2 | B4: FII | C4: 0.5 | D4: 0.07

Sheet INVESTIMENTOS
B2: DATA | C2: NOME | D2: QTD | E2: VALOR UNIT | F2: VALOR TOTAL
B3: 45658 | C3: CORP11 | D3: 30 | E3: R$ 10,00 | F3: 180
B4: 45658 | C4: OFFI11 | D4: 0,5 | E4: R$ 1.000,00 | F4: 200
B5: 45658 | C5: CENT11 | D5: 80 | E5: R$ 5,45 | F5: R$ 514,54
B6: 45658 | C6: LOGS11 | D6: 7 | E6: R$ 4,22 | F6: R$ 33,76
B7: 45658 | C7: GALP11 | D7: 20 | E7: R$ 9,99 | F7: R$ 219,78
B8: 45658 | C8: ROTA11 | D8: 0,8508 | E8: R$ 500,00 | F8: R$ 425,40
B9: 45658 | C9: SHOP11 | D9: 0,0993 | E9: R$ 3.500,00 | F9: R$ 347,55
B10: 45658 | C10: MALL11 | D10: 0,005 | E10: R$ 9.999,00 | F10: R$ 50,00
B11: 45658 | C11: VEND11 | D11: 56 | E11: R$ 3,21 | F11: R$ 179,76
B12: 45658 | C12: CRED11 | D12: 64 | E12: R$ 8,78 | F12: R$ 561,92
B13: 45659 | C13: SHOP11 | D13: 85 | E13: R$ 9,60 | F13: R$ 816,00
B14: 45659 | C14: MALL11 | D14: 0,8468 | E14: R$ 970,00 | F14: R$ 821,40
B15: 45659 | C15: CENT11 | D15: 76 | E15: R$ 4,91 | F15: R$ 372,78
B16: 45659 | C16: LOGS11 | D16: 40 | E16: R$ 4,35 | F16: R$ 173,86
B17: 45659 | C17: OFFI11 | D17: 85 | E17: R$ 10,19 | F17: R$ 866,13
B18: 45659 | C18: CORP11 | D18: 0,1967 | E18: R$ 465,00 | F18: R$ 91,47
B19: 45659 | C19: OFFI11 | D19: 0,2004 | E19: R$ 3.850,00 | F19: R$ 771,54
B20: 45659 | C20: VEND11 | D20: 0,008 | E20: R$ 8.999,10 | F20: R$ 71,99
B21: 45659 | C21: OFFI11 | D21: 53 | E21: R$ 3,08 | F21: R$ 163,32
B22: 45659 | C22: CENT11 | D22: 76 | E22: R$ 9,66 | F22: R$ 734,01
B23: 45660 | C23: LOGS11 | D23: 59 | E23: R$ 11,00 | F23: R$ 649,00
B24: 45660 | C24: LOGS11 | D24: 0,1512 | E24: 930 | F24: R$ 145,15
B25: 45660 | C25: VEND11 | D25: 68 | E25: R$ 5,07 | F25: R$ 344,66
B26: 45660 | C26: LOGS11 | D26: 85 | E26: R$ 4,14 | F26: R$ 351,53
B27: 45660 | C27: MALL11 | D27: 94 | E27: R$ 10,29 | F27: R$ 967,23
B28: 45660 | C28: LOGS11 | D28: 0,0619 | E28: 350 | F28: R$ 29,71
B29: 45660 | C29: CENT11 | D29: 0,0785 | E29: R$ 3.360,00 | F29: R$ 263,76
B30: 45660 | C30: MALL11 | D30: 0,005 | E30: R$ 9.599,04 | F30: R$ 48,00
B31: 45660 | C31: ROTA11 | D31: 66 | E31: R$ 2,89 | F31: R$ 190,67
B32: 45660 | C32: LOGS11 | D32: 79 | E32: R$ 7,90 | F32: R$ 624,26

Sheet DIVIDENDOS e SAQUES
A2: DATA | B2: NOME | C2: QTD | D2: VALOR UNIT | E2: TOTAL | F2: TIPO
A3: 16/1/2025 | B3: CORP11 | C3: 0,2731 | D3: R$ 1.100,00 | E3: R$ 300,41 | F3: DIVIDENDO
A4: 16/1/2025 | B4: OFFI11 | C4: 8 | D4: R$ 0,42 | E4: R$ 3,38 | F4: DIVIDENDO
A5: 16/1/2025 | B5: CENT11 | C5: 22 | D5: R$ 1,00 | E5: R$ 21,98 | F5: SAQUE
A6: 16/1/2025 | B6: LOGS11 | C6: 0,8508 | D6: R$ 550,00 | E6: R$ 467,94 | F6: DIVIDENDO
A7: 16/1/2025 | B7: GALP11 | C7: 0,0993 | D7: R$ 3.850,00 | E7: R$ 382,31 | F7: SAQUE
A8: 16/2/2025 | B8: ROTA11 | C8: 0,8468 | D8: R$ 1.067,00 | E8: R$ 903,54 | F8: DIVIDENDO
A9: 16/2/2025 | B9: SHOP11 | C9: 40 | D9: R$ 0,43 | E9: R$ 17,39 | F9: SAQUE
A10: 16/2/2025 | B10: MALL11 | C10: 85 | D10: R$ 1,02 | E10: R$ 86,61 | F10: SAQUE
A11: 16/2/2025 | B11: VEND11 | C11: 0,1967 | D11: R$ 511,50 | E11: R$ 100,61 | F11: DIVIDENDO
A12: 16/2/2025 | B12: CRED11 | C12: 0,2004 | D12: R$ 4.235,00 | E12: R$ 848,69 | F12: DIVIDENDO

Sheet RELATÓRIOS
A1: Resumo Geral
C2: 1 INVENTIMENTOS. | E2: 2 QUANTIDADES E TOTAIS COMPRADOS. | K2: 3 DIVIDENDOS e SAQUES
A3: Total Investido | B3: =SUM(INVESTIMENTOS!G:G) -> 0
A4: Total Dividendos Recebidos | B4: =SUM('DIVIDENDOS e SAQUES'!E:E) -> 0 | C4: NOME | D4: (vazio) | F4: Dados | L4: Rótulos de coluna
A5: Resultado Total | B5: =B4-B3 -> 0 | C5: CORP11 | E5: NOME | F5: QTD TOTAL | G5: COMPRA TOTAL | L5: DIVIDENDO | N5: SAQUE
C6: OFFI11 | E6: CORP11 | F6: 164 | G6: R$ 1.665,00 | K6: NOME | L6: VALOR TOTAL | M6: QTD TOTAL | N6: VALOR TOTAL | O6: QTD TOTAL
C7: CENT11 | E7: OFFI11 | F7: 12711 | G7: R$ 1.239,65 | K7: CORP11 | N7: R$ 1.363,61 | O7: 12711
C8: LOGS11 | E8: CENT11 | F8: 239 | G8: R$ 1.235,19 | K8: OFFI11 | L8: R$ 55,92 | M8: 133
C9: GALP11 | E9: LOGS11 | F9: 133 | G9: R$ 559,15 | K9: CENT11 | L9: R$ 205,31 | M9: 201
C10: ROTA11 | E10: GALP11 | F10: 201 | G10: R$ 2.053,14 | K10: LOGS11 | N10: R$ 601,24 | O10: 11094
C11: SHOP11 | E11: ROTA11 | F11: 11094 | G11: R$ 546,58 | K11: GALP11 | N11: R$ 1.521,14 | O11: 0,3782
C12: MALL11 | E12: SHOP11 | F12: 0,3782 | G12: R$ 1.382,85
C13: VEND11 | E13: MALL11 | F13: 0,018 | G13: R$ 169,98
C14: CRED11 | E14: VEND11 | F14: 175 | G14: R$ 533,76
E15: CRED11 | F15: 219 | G15: R$ 1.920,19

Sheet FLUXOS
A2: Mês | B2: Aporte | C2: Dividendos | D2: Fluxo Líquido
A3: 1 | B3: -1000 | C3: =1000*AVERAGE(CARTEIRA!D3:D4)/12 -> 6.25 | D3: =B3+C3 -> -993.75
A4: 2 | B4: -1000 | C4: =1000*AVERAGE(CARTEIRA!D3:D4)/12 -> 6.25 | D4: =B4+C4 -> -993.75
A5: 3 | B5: -1000 | C5: =1000*AVERAGE(CARTEIRA!D3:D4)/12 -> 6.25 | D5: =B5+C5 -> -993.75
A6: 4 | B6: -1000 | C6: =1000*AVERAGE(CARTEIRA!D3:D4)/12 -> 6.25 | D6: =B6+C6 -> -993.75
A7: 5 | B7: -1000 | C7: =1000*AVERAGE(CARTEIRA!D3:D4)/12 -> 6.25 | D7: =B7+C7 -> -993.75
A8: 6 | B8: -1000 | C8: =1000*AVERAGE(CARTEIRA!D3:D4)/12 -> 6.25 | D8: =B8+C8 -> -993.75
A9: 7 | B9: -1000 | C9: =1000*AVERAGE(CARTEIRA!D3:D4)/12 -> 6.25 | D9: =B9+C9 -> -993.75
A10: 8 | B10: -1000 | C10: =1000*AVERAGE(CARTEIRA!D3:D4)/12 -> 6.25 | D10: =B10+C10 -> -993.75
A11: 9 | B11: -1000 | C11: =1000*AVERAGE(CARTEIRA!D3:D4)/12 -> 6.25 | D11: =B11+C11 -> -993.75
A12: 10 | B12: -1000 | C12: =1000*AVERAGE(CARTEIRA!D3:D4)/12 -> 6.25 | D12: =B12+C12 -> -993.75
A13: 11 | B13: -1000 | C13: =1000*AVERAGE(CARTEIRA!D3:D4)/12 -> 6.25 | D13: =B13+C13 -> -993.75
A14: 12 | B14: -1000 | C14: =1000*AVERAGE(CARTEIRA!D3:D4)/12 -> 6.25 | D14: =B14+C14 -> -993.75
A15: 13 | B15: -1000 | C15: =1000*AVERAGE(CARTEIRA!D3:D4)/12 -> 6.25 | D15: =B15+C15 -> -993.75
A16: 14 | B16: -1000 | C16: =1000*AVERAGE(CARTEIRA!D3:D4)/12 -> 6.25 | D16: =B16+C16 -> -993.75
A17: 15 | B17: -1000 | C17: =1000*AVERAGE(CARTEIRA!D3:D4)/12 -> 6.25 | D17: =B17+C17 -> -993.75
A18: 16 | B18: -1000 | C18: =1000*AVERAGE(CARTEIRA!D3:D4)/12 -> 6.25 | D18: =B18+C18 -> -993.75
A19: 17 | B19: -1000 | C19: =1000*AVERAGE(CARTEIRA!D3:D4)/12 -> 6.25 | D19: =B19+C19 -> -993.75
A20: 18 | B20: -1000 | C20: =1000*AVERAGE(CARTEIRA!D3:D4)/12 -> 6.25 | D20: =B20+C20 -> -993.75
A21: 19 | B21: -1000 | C21: =1000*AVERAGE(CARTEIRA!D3:D4)/12 -> 6.25 | D21: =B21+C21 -> -993.75
A22: 20 | B22: -1000 | C22: =1000*AVERAGE(CARTEIRA!D3:D4)/12 -> 6.25 | D22: =B22+C22 -> -993.75
A23: 21 | B23: -1000 | C23: =1000*AVERAGE(CARTEIRA!D3:D4)/12 -> 6.25 | D23: =B23+C23 -> -993.75
A24: 22 | B24: -1000 | C24: =1000*AVERAGE(CARTEIRA!D3:D4)/12 -> 6.25 | D24: =B24+C24 -> -993.75
A25: 23 | B25: -1000 | C25: =1000*AVERAGE(CARTEIRA!D3:D4)/12 -> 6.25 | D25: =B25+C25 -> -993.75
A26: 24 | B26: -1000 | C26: =1000*AVERAGE(CARTEIRA!D3:D4)/12 -> 6.25 | D26: =B26+C26 -> -993.75
A27: 25 | B27: -1000 | C27: =1000*AVERAGE(CARTEIRA!D3:D4)/12 -> 6.25 | D27: =B27+C27 -> -993.75
A28: 26 | B28: -1000 | C28: =1000*AVERAGE(CARTEIRA!D3:D4)/12 -> 6.25 | D28: =B28+C28 -> -993.75
A29: 27 | B29: -1000 | C29: =1000*AVERAGE(CARTEIRA!D3:D4)/12 -> 6.25 | D29: =B29+C29 -> -993.75
A30: 28 | B30: -1000 | C30: =1000*AVERAGE(CARTEIRA!D3:D4)/12 -> 6.25 | D30: =B30+C30 -> -993.75
A31: 29 | B31: -1000 | C31: =1000*AVERAGE(CARTEIRA!D3:D4)/12 -> 6.25 | D31: =B31+C31 -> -993.75
A32: 30 | B32: -1000 | C32: =1000*AVERAGE(CARTEIRA!D3:D4)/12 -> 6.25 | D32: =B32+C32 -> -993.75
A33: 31 | B33: -1000 | C33: =1000*AVERAGE(CARTEIRA!D3:D4)/12 -> 6.25 | D33: =B33+C33 -> -993.75
A34: 32 | B34: -1000 | C34: =1000*AVERAGE(CARTEIRA!D3:D4)/12 -> 6.25 | D34: =B34+C34 -> -993.75
A35: 33 | B35: -1000 | C35: =1000*AVERAGE(CARTEIRA!D3:D4)/12 -> 6.25 | D35: =B35+C35 -> -993.75
A36: 34 | B36: -1000 | C36: =1000*AVERAGE(CARTEIRA!D3:D4)/12 -> 6.25 | D36: =B36+C36 -> -993.75
A37: 35 | B37: -1000 | C37: =1000*AVERAGE(CARTEIRA!D3:D4)/12 -> 6.25 | D37: =B37+C37 -> -993.75
A38: 36 | B38: -1000 | C38: =1000*AVERAGE(CARTEIRA!D3:D4)/12 -> 6.25 | D38: =B38+C38 -> -993.75
A39: 37 | B39: -1000 | C39: =1000*AVERAGE(CARTEIRA!D3:D4)/12 -> 6.25 | D39: =B39+C39 -> -993.75
A40: 38 | B40: -1000 | C40: =1000*AVERAGE(CARTEIRA!D3:D4)/12 -> 6.25 | D40: =B40+C40 -> -993.75
A41: 39 | B41: -1000 | C41: =1000*AVERAGE(CARTEIRA!D3:D4)/12 -> 6.25 | D41: =B41+C41 -> -993.75
...
